<?xml version="1.0"?>
<robot name="swarm_bot" xmlns:xacro="http://www.ros.org/wiki/xacro">

  <xacro:property name="base_length" value="0.30"/>
  <xacro:property name="base_width" value="0.20"/>
  <xacro:property name="base_height" value="0.06"/>

  <xacro:property name="wheel_radius" value="0.05"/>
  <xacro:property name="wheel_width" value="0.03"/>
  <xacro:property name="wheel_y_offset" value="0.115"/>
  <xacro:property name="wheel_x_offset" value="0.0"/>

  <xacro:property name="caster_radius" value="0.025"/>
  <xacro:property name="caster_x_offset" value="-0.11"/>

  <material name="blue">
    <color rgba="0.2 0.4 0.9 1.0"/>
  </material>

  <material name="black">
    <color rgba="0.1 0.1 0.1 1.0"/>
  </material>

  <material name="gray">
    <color rgba="0.6 0.6 0.6 1.0"/>
  </material>

  <link name="base_footprint"/>

  <link name="base_link">
    <visual>
      <origin xyz="0 0 ${wheel_radius + base_height/2}" rpy="0 0 0"/>
      <geometry>
        <box size="${base_length} ${base_width} ${base_height}"/>
      </geometry>
      <material name="blue"/>
    </visual>
    <collision>
      <origin xyz="0 0 ${wheel_radius + base_height/2}" rpy="0 0 0"/>
      <geometry>
        <box size="${base_length} ${base_width} ${base_height}"/>
      </geometry>
    </collision>
    <inertial>
      <origin xyz="0 0 ${wheel_radius + base_height/2}" rpy="0 0 0"/>
      <mass value="2.0"/>
      <inertia ixx="0.02" ixy="0.0" ixz="0.0" iyy="0.03" iyz="0.0" izz="0.04"/>
    </inertial>
  </link>

  <joint name="base_footprint_joint" type="fixed">
    <parent link="base_footprint"/>
    <child link="base_link"/>
    <origin xyz="0 0 0" rpy="0 0 0"/>
  </joint>

  <link name="left_wheel">
    <visual>
      <origin xyz="0 0 0" rpy="1.5708 0 0"/>
      <geometry>
        <cylinder radius="${wheel_radius}" length="${wheel_width}"/>
      </geometry>
      <material name="black"/>
    </visual>
    <collision>
      <origin xyz="0 0 0" rpy="1.5708 0 0"/>
      <geometry>
        <cylinder radius="${wheel_radius}" length="${wheel_width}"/>
      </geometry>
    </collision>
    <inertial>
      <mass value="0.2"/>
      <inertia ixx="0.0005" ixy="0.0" ixz="0.0" iyy="0.0005" iyz="0.0" izz="0.0005"/>
    </inertial>
  </link>

  <link name="right_wheel">
    <visual>
      <origin xyz="0 0 0" rpy="1.5708 0 0"/>
      <geometry>
        <cylinder radius="${wheel_radius}" length="${wheel_width}"/>
      </geometry>
      <material name="black"/>
    </visual>
    <collision>
      <origin xyz="0 0 0" rpy="1.5708 0 0"/>
      <geometry>
        <cylinder radius="${wheel_radius}" length="${wheel_width}"/>
      </geometry>
    </collision>
    <inertial>
      <mass value="0.2"/>
      <inertia ixx="0.0005" ixy="0.0" ixz="0.0" iyy="0.0005" iyz="0.0" izz="0.0005"/>
    </inertial>
  </link>

  <joint name="left_wheel_joint" type="continuous">
    <parent link="base_link"/>
    <child link="left_wheel"/>
    <origin xyz="${wheel_x_offset} ${wheel_y_offset} ${wheel_radius}" rpy="0 0 0"/>
    <axis xyz="0 1 0"/>
  </joint>

  <joint name="right_wheel_joint" type="continuous">
    <parent link="base_link"/>
    <child link="right_wheel"/>
    <origin xyz="${wheel_x_offset} -${wheel_y_offset} ${wheel_radius}" rpy="0 0 0"/>
    <axis xyz="0 1 0"/>
  </joint>

  <link name="rear_caster">
    <visual>
      <origin xyz="0 0 0" rpy="0 0 0"/>
      <geometry>
        <sphere radius="${caster_radius}"/>
      </geometry>
      <material name="gray"/>
    </visual>
    <collision>
      <origin xyz="0 0 0" rpy="0 0 0"/>
      <geometry>
        <sphere radius="${caster_radius}"/>
      </geometry>
    </collision>
    <inertial>
      <mass value="0.05"/>
      <inertia ixx="0.0001" ixy="0.0" ixz="0.0" iyy="0.0001" iyz="0.0" izz="0.0001"/>
    </inertial>
  </link>

  <joint name="rear_caster_joint" type="fixed">
    <parent link="base_link"/>
    <child link="rear_caster"/>
    <origin xyz="${caster_x_offset} 0 ${caster_radius}" rpy="0 0 0"/>
  </joint>

  <gazebo>
    <plugin filename="gz-sim-diff-drive-system" name="gz::sim::systems::DiffDrive">
      <left_joint>left_wheel_joint</left_joint>
      <right_joint>right_wheel_joint</right_joint>
      <wheel_separation>${2.0 * wheel_y_offset}</wheel_separation>
      <wheel_radius>${wheel_radius}</wheel_radius>
      <max_linear_acceleration>1.0</max_linear_acceleration>
      <max_angular_acceleration>2.0</max_angular_acceleration>
      <odom_topic>odom</odom_topic>
      <tf_topic>tf</tf_topic>
      <frame_id>odom</frame_id>
      <child_frame_id>base_footprint</child_frame_id>
    </plugin>

    <plugin filename="gz-sim-joint-state-publisher-system" name="gz::sim::systems::JointStatePublisher"/>
  </gazebo>

</robot>